<?xml version="1.0"?>
<robot name="my_robot">

    <link name="base_footprint"/>

    <joint name="base_footprint_joint" type="fixed">
        <parent link="base_footprint"/>
        <child link="base_link"/>
        <origin xyz="0 0 0.06"  rpy="0 0 0"/>
    </joint>

    <link name ="base_link">
        <visual>
            <geometry>
                <box size ="0.20 0.20 0.10"/>
            </geometry>
            <material name = "green">
                <color rgba ="0 1 0 1"/>
            </material>
            <origin xyz = "0 0 0.05" rpy="0 0 0" />
        </visual>
        <inertial>
            <mass value="3.0"/>
            <inertia ixx="0.012500000000000002" ixy="0.0" ixz="0.0" iyy="0.012500000000000002" iyz="0.0" izz="0.020000000000000004"/>
        </inertial>

        <collision>
            <geometry>
                <box size ="0.20 0.20 0.10"/>
            </geometry>
        </collision>
    </link>


    <joint name="imu_joint" type="fixed">
        <origin xyz="0 0 0.1125" rpy="0 0 0"/>
        <parent link="base_link"/>
        <child link="imu_link"/>
    </joint>

    <link name="imu_link">
        <collision>
        <geometry>
            <cylinder length ="0.025" radius="0.03"/>
        </geometry>
        </collision>
        <visual>
        <geometry>
            <cylinder length ="0.025" radius="0.03"/>
        </geometry>
        <material name="red">
            <color rgba="1 0 0 1"/>
        </material>

        </visual>
        <inertial>
            <mass value="0.005"/>
            <inertia ixx="0.1" ixy="0.0" ixz="0.0" iyy="0.1" iyz="0.0" izz="0.1"/>
        </inertial>


    </link>

    <link name='right_wheel'>
        <visual>
            <geometry>
                <cylinder length ="0.05" radius="0.06"/>
            </geometry>
            <material name="red">
                <color rgba="1 0 0 1"/>
            </material>
            <origin xyz ="0 0 0" rpy ="0 0 0"/>
        </visual>
        <inertial>
            <mass value="0.3"/>
            <inertia ixx="0.0002775" ixy="0.0" ixz="0.0" iyy="0.0002775" iyz="0.0" izz="0.00037500000000000006"/>
        </inertial>

        <collision>
            <geometry>
                <cylinder length ="0.05" radius="0.06"/>
            </geometry>
        </collision>
    </link>

    <joint name="right_wheel_joint" type="continuous">
        <parent link="base_link"/>
        <child link="right_wheel"/>
        <origin xyz="-0.032 -0.125 0" rpy="1.57 0 0"/>
        <axis xyz="0 0 -1"/>
    </joint>

    <link name="left_wheel">
        <visual>
            <geometry>
                <cylinder length="0.05" radius="0.06"/>
            </geometry>
            <material name="red"/>
            <origin xyz="0 0 0" rpy="0 0 0"/>
        </visual>
        <inertial>
            <mass value="0.3"/>
            <inertia ixx="0.0002775" ixy="0.0" ixz="0.0" iyy="0.0002775" iyz="0.0" izz="0.00037500000000000006"/>
        </inertial>
        <collision>
            <geometry>
                <cylinder length="0.05" radius="0.06"/>
            </geometry>
        </collision>
    </link>

    <joint name="left_wheel_joint" type="continuous">
        <parent link="base_link"/>
        <child link="left_wheel"/>
        <origin xyz="-0.032 0.125 0" rpy="1.57 0 0"/>
        <axis xyz="0 0 -1"/>
    </joint>

    <link name="caster_wheel">
        <visual>
            <geometry>
                <sphere radius="0.03"/>
            </geometry>
            <material name="red"/>
            <origin xyz="0 0 0" rpy="0 0 0"/>
        </visual>
        <inertial>
            <mass value="1"/>
            <inertia ixx="0.00035999999999999997" ixy="0.0" ixz="0.0" iyy="0.00035999999999999997" iyz="0.0" izz="0.00035999999999999997"/>
        </inertial>
        <collision>
            <geometry>
                <sphere radius="0.03"/>
            </geometry>
        </collision>

    </link>

    <joint name="caster_wheel_joint" type="continuous">
        <parent link="base_link"/>
        <child link="caster_wheel"/>
        <origin xyz="0.06 0 -0.03" rpy="0 0 0"/>
        <axis xyz="0 1 0"/>
    </joint>

    <gazebo>
        <plugin filename="gz-sim-diff-drive-system"
                name="gz::sim::systems::DiffDrive">
            <left_joint>left_wheel_joint</left_joint>
            <right_joint>right_wheel_joint</right_joint>
            <wheel_separation>0.20</wheel_separation>
            <wheel_radius>0.06</wheel_radius>
            <odom_publish_frequency>1</odom_publish_frequency>
            <topic>cmd_vel</topic>
        </plugin>
    </gazebo>

    <gazebo>
        <plugin
            filename="gz-sim-sensors-system"
            name="gz::sim::systems::Sensors">
            <render_engine>ogre2</render_engine>
        </plugin>
    </gazebo>

    <gazebo>
        <plugin
        filename="gz-sim-scene-broadcaster-system"
        name="gz::sim::systems::SceneBroadcaster">
        </plugin>
    </gazebo>


    <gazebo reference="imu_link">
        <sensor name="imu_sensor" type="imu">
            <pose>0 0 0 0 0 0</pose>
            <always_on>1</always_on>
            <update_rate>1</update_rate>
            <visualize>true</visualize>
            <topic>imu</topic>
        </sensor>
    </gazebo>

    <gazebo reference="imu_link">
        <sensor name='gpu_lidar' type='gpu_lidar'>
            <gz_frame_id>imu_link</gz_frame_id>
            <pose>0 0 0 0 0 0</pose>
            <topic>lidar</topic>
            <update_rate>1</update_rate>
            <ray>
                <scan>
                    <horizontal>
                        <samples>640</samples>
                        <resolution>1</resolution>
                        <min_angle>-1.396263</min_angle>
                        <max_angle>1.396263</max_angle>
                    </horizontal>
                    <vertical>
                        <samples>1</samples>
                        <resolution>0.01</resolution>
                        <min_angle>0</min_angle>
                        <max_angle>0</max_angle>
                    </vertical>
                </scan>
                <range>
                    <min>0.08</min>
                    <max>10.0</max>
                    <resolution>0.01</resolution>
                </range>
            </ray>
            <always_on>1</always_on>
            <visualize>true</visualize>
        </sensor>
    </gazebo>

    <gazebo reference="imu_link">
        <sensor name="rgbd_camera" type="rgbd_camera">
          <update_rate>10</update_rate>
          <topic>rgbd_camera</topic>
          <camera>
            <horizontal_fov>1.05</horizontal_fov>
            <image>
              <width>256</width>
              <height>256</height>
            </image>
            <clip>
              <near>0.1</near>
              <far>10.0</far>
            </clip>
          </camera>
        </sensor>
    </gazebo>




</robot>        